Workbook

Sheet RESUMEN
A1: LanternGuard, prototipo simple Ø200 (nodo V2 + boya): masa impresa, horas y costo
A2: Parametros (amarillo = entrada; vienen de params.py) | C2: nombre en params.py
A3: Densidad del PETG g/cm³ (estimado) | B3: 1.27 | C3: petg.densidad
A4: Impresora g/h (estimado) | B4: 15 | C4: costo.g_por_h
A5: Filamento soles/kg (estimado) | B5: 90 | C5: costo.filamento_soles_kg
A9: grupo | B9: masa impresa g (estimado o slicer) | C9: horas (estimado o slicer) | D9: costo filamento S/ | E9: costo hardware S/ | F9: total S/
A10: nodo simple | B10: =SUMIF(PIEZAS!$B:$B,$A10,PIEZAS!$N:$N) | C10: =SUMIF(PIEZAS!$B:$B,$A10,PIEZAS!$P:$P) | D10: =SUMIF(PIEZAS!$B:$B,$A10,PIEZAS!$Q:$Q) | E10: =SUMIF(HARDWARE!$A:$A,$A10,HARDWARE!$F:$F) | F10: =D10+E10
A11: linterna de prueba | B11: =SUMIF(PIEZAS!$B:$B,$A11,PIEZAS!$N:$N) | C11: =SUMIF(PIEZAS!$B:$B,$A11,PIEZAS!$P:$P) | D11: =SUMIF(PIEZAS!$B:$B,$A11,PIEZAS!$Q:$Q) | E11: =SUMIF(HARDWARE!$A:$A,$A11,HARDWARE!$F:$F) | F11: =D11+E11
A12: boya simple | B12: =SUMIF(PIEZAS!$B:$B,$A12,PIEZAS!$N:$N) | C12: =SUMIF(PIEZAS!$B:$B,$A12,PIEZAS!$P:$P) | D12: =SUMIF(PIEZAS!$B:$B,$A12,PIEZAS!$Q:$Q) | E12: =SUMIF(HARDWARE!$A:$A,$A12,HARDWARE!$F:$F) | F12: =D12+E12
A13: modular D200 | B13: =SUMIF(PIEZAS!$B:$B,$A13,PIEZAS!$N:$N) | C13: =SUMIF(PIEZAS!$B:$B,$A13,PIEZAS!$P:$P) | D13: =SUMIF(PIEZAS!$B:$B,$A13,PIEZAS!$Q:$Q) | E13: =SUMIF(HARDWARE!$A:$A,$A13,HARDWARE!$F:$F) | F13: =D13+E13
A14: nodo simple + linterna + boya | B14: =SUM(B10:B12) | C14: =SUM(C10:C12) | D14: =SUM(D10:D12) | E14: =SUM(E10:E12) | F14: =SUM(F10:F12)
A16: Masa por pieza = la misma del calculo de flotacion (piel + relleno de cada pieza). Llenar los precios amarillos de HARDWARE para el costo total. La fila modular D200 es para comparar.

Sheet PIEZAS
A1: pieza | B1: grupo | C1: descripcion | D1: cantidad | E1: X mm (orientacion de impresion) | F1: Y mm | G1: Z mm | H1: volumen solido cm³ (CadQuery) | I1: orientacion | J1: soportes | K1: relleno_% | L1: fraccion maciza (piel + relleno) | M1: masa por pieza g (estimado o slicer) | N1: masa total g | O1: horas por pieza (estimado o slicer) | P1: horas total | Q1: costo S/ | R1: fuente masa y horas
A2: M1s_caja_cuerpo | B2: nodo simple | C2: M1 caja baja con bolsillos | D2: 1 | E2: 147 | F2: 146 | G2: 102.5 | H2: 349.39 | I2: X180 | J2: si | K2: 100 % | L2: 1 | M2: =H2*RESUMEN!$B$3*L2 | N2: =M2*D2 | O2: =M2/RESUMEN!$B$4 | P2: =O2*D2 | Q2: =N2/1000*RESUMEN!$B$5 | R2: estimado
A3: M2_caja_tapa | B3: nodo simple | C3: M2 caja, tapa con asa | D3: 1 | E3: 63 | F3: 146 | G3: 147 | H3: 136 | I3: Y+90 | J3: si | K3: 100 % | L3: 1 | M3: =H3*RESUMEN!$B$3*L3 | N3: =M3*D3 | O3: =M3/RESUMEN!$B$4 | P3: =O3*D3 | Q3: =N3/1000*RESUMEN!$B$5 | R3: estimado
A4: M3s_riel_gancho | B4: nodo simple | C4: M3s riel con gancho, mitad | D4: 2 | E4: 141.5 | F4: 77.2 | G4: 50 | H4: 85.28 | I4: X+90 | J4: si | K4: riel 40 %, gancho 100 % | L4: 0.824 | M4: =H4*RESUMEN!$B$3*L4 | N4: =M4*D4 | O4: =M4/RESUMEN!$B$4 | P4: =O4*D4 | Q4: =N4/1000*RESUMEN!$B$5 | R4: estimado
A5: M3t_tapa_bolsillo | B5: nodo simple | C5: M3t tapa del bolsillo | D5: 2 | E5: 117 | F5: 32 | G5: 3 | H5: 11.14 | I5: X180 | J5: no | K5: 100 % | L5: 1 | M5: =H5*RESUMEN!$B$3*L5 | N5: =M5*D5 | O5: =M5/RESUMEN!$B$4 | P5: =O5*D5 | Q5: =N5/1000*RESUMEN!$B$5 | R5: estimado
A6: M5s_capsula_tapa_pie | B6: nodo simple | C6: M5s tapa con pie | D6: 2 | E6: 59.2 | F6: 64 | G6: 95.9 | H6: 76.04 | I6: sin girar | J6: si | K6: 100 % | L6: 1 | M6: =H6*RESUMEN!$B$3*L6 | N6: =M6*D6 | O6: =M6/RESUMEN!$B$4 | P6: =O6*D6 | Q6: =N6/1000*RESUMEN!$B$5 | R6: estimado
A7: M11_bandeja | B7: nodo simple | C7: M11 bandeja (M11_bandeja) | D7: 1 | E7: 115 | F7: 114 | G7: 30 | H7: 39.91 | I7: sin girar | J7: no | K7: 40 % | L7: 0.909 | M7: =H7*RESUMEN!$B$3*L7 | N7: =M7*D7 | O7: =M7/RESUMEN!$B$4 | P7: =O7*D7 | Q7: =N7/1000*RESUMEN!$B$5 | R7: estimado
A8: M11_bandeja_sup | B8: nodo simple | C8: M11 bandeja (M11_bandeja_sup) | D8: 1 | E8: 115 | F8: 114 | G8: 3 | H8: 38.06 | I8: sin girar | J8: no | K8: 40 % | L8: 0.91 | M8: =H8*RESUMEN!$B$3*L8 | N8: =M8*D8 | O8: =M8/RESUMEN!$B$4 | P8: =O8*D8 | Q8: =N8/1000*RESUMEN!$B$5 | R8: estimado
A9: M4_capsula_cuerpo | B9: nodo simple | C9: M4 capsula, cuerpo | D9: 2 | E9: 64 | F9: 64 | G9: 44 | H9: 45.95 | I9: Y-90 | J9: si | K9: 100 % | L9: 1 | M9: =H9*RESUMEN!$B$3*L9 | N9: =M9*D9 | O9: =M9/RESUMEN!$B$4 | P9: =O9*D9 | Q9: =N9/1000*RESUMEN!$B$5 | R9: estimado
A10: M6_capsula_bisel | B10: nodo simple | C10: M6 bisel | D10: 2 | E10: 42 | F10: 42 | G10: 2.5 | H10: 1.89 | I10: Y+90 | J10: no | K10: 40 % | L10: 1 | M10: =H10*RESUMEN!$B$3*L10 | N10: =M10*D10 | O10: =M10/RESUMEN!$B$4 | P10: =O10*D10 | Q10: =N10/1000*RESUMEN!$B$5 | R10: estimado
A11: LR1_separador | B11: linterna de prueba | C11: LR1 separador | D11: 1 | E11: 211.9 | F11: 211.9 | G11: 6 | H11: 44.86 | I11: sin girar | J11: no | K11: 40 % | L11: 0.766 | M11: =H11*RESUMEN!$B$3*L11 | N11: =M11*D11 | O11: =M11/RESUMEN!$B$4 | P11: =O11*D11 | Q11: =N11/1000*RESUMEN!$B$5 | R11: estimado
A12: B1s_casco | B12: boya simple | C12: B1s casco | D12: 1 | E12: 240 | F12: 220 | G12: 125 | H12: 753.49 | I12: X180 | J12: si | K12: 100 % | L12: 1 | M12: =H12*RESUMEN!$B$3*L12 | N12: =M12*D12 | O12: =M12/RESUMEN!$B$4 | P12: =O12*D12 | Q12: =N12/1000*RESUMEN!$B$5 | R12: estimado
A13: B2s_tapa | B13: boya simple | C13: B2s tapa | D13: 1 | E13: 9 | F13: 220 | G13: 240 | H13: 260.46 | I13: Y+90 | J13: si | K13: 100 % | L13: 1 | M13: =H13*RESUMEN!$B$3*L13 | N13: =M13*D13 | O13: =M13/RESUMEN!$B$4 | P13: =O13*D13 | Q13: =N13/1000*RESUMEN!$B$5 | R13: estimado
... A32: M14_pestillo | B32: modular D200 | C32: Pestillo | D32: 2 | E32: 12 | F32: 35.2 | G32: 3.6 | H32: 0.92 | I32: X+90 | J32: no | K32: 40 % | L32: 1 | M32: =H32*RESUMEN!$B$3*L32 | N32: =M32*D32 | O32: =M32/RESUMEN!$B$4 | P32: =O32*D32 | Q32: =N32/1000*RESUMEN!$B$5 | R32: estimado
A34: Soportes: voladizo en la orientacion de impresion > 300 mm². Masa = volumen x densidad x fraccion maciza (piel de impresion.cascara + relleno); horas = masa / g por hora (RESUMEN).

Sheet HARDWARE
A1: grupo | B1: item | C1: medida | D1: cantidad | E1: precio unitario S/ (llenar) | F1: subtotal S/
A2: nodo simple | B2: Tornillo M3 x 12 + inserto termico M3 (tapa de la caja) | C2: M3 | D2: 12 | F2: =D2*E2
A3: nodo simple | B3: Tornillo M3 x 8 + inserto termico M3 (bandejas) | C3: M3 | D3: 4 | F3: =D3*E3
A4: nodo simple | B4: Tornillo M3 x 16 + tuerca (capsulas) | C4: M3 | D4: 8 | F4: =D4*E4
A5: nodo simple | B5: Tornillo M2 autorroscante (bisel) | C5: M2 x 6 | D5: 6 | F5: =D5*E5
A6: nodo simple | B6: Cordon de junta torica Ø2 (caja + 2 capsulas, +10 %) | C6: 970 mm | D6: 1 | F6: =D6*E6
A7: nodo simple | B7: Prensaestopas PG7 con contratuerca (3 caja + 2 capsulas) | C7: PG7 | D7: 5 | F7: =D7*E7
A8: nodo simple | B8: Disco de acrilico de la ventana | C8: Ø30 x 3 | D8: 2 | F8: =D8*E8
A9: nodo simple | B9: Grillete o argolla de inox (izado) | C9: M6 | D9: 1 | F9: =D9*E9
A10: nodo simple | B10: Tornillo M4 x 20 + inserto termico M4 (bridas del riel a la caja) | C10: M4 | D10: 8 | F10: =D10*E10
A11: nodo simple | B11: Tornillo M3 x 8 avellanado + inserto M3 (tapas del bolsillo) | C11: M3 | D11: 4 | F11: =D11*E11
A12: nodo simple | B12: Tornillo M4 x 45 + tuerca (pie de las capsulas) | C12: M4 | D12: 4 | F12: =D12*E12
A13: nodo simple | B13: Correa textil | C13: 25 x 300 mm | D13: 2 | F13: =D13*E13
... A44: modular D200 | B44: Pletina de inox | C44: 25 x 5 x 100 | D44: 4 | F44: =D44*E44

Sheet DISEÑO
A1: concepto | B1: valor | C1: unidad | D1: de donde sale
A2: Riel: largo / seccion x pared | B2: 430 / 30 x 4 | C2: mm | D2: params.py simple.riel_L, riel.*
A3: Caja: ESP32 y pisos | B3: kit_a, 2 pisos | C3: - | D3: params.py simple.esp32_base (equipo), simple.caja_pisos
A4: Caja: exterior (sin brida) | B4: 127.0 x 126.0 x 77.0 | C4: mm | D4: layout.py (derivado de la electronica)
A5: Caja: con brida | B5: 147.0 x 146.0 | C5: mm | D5: layout.py + caja.brida_ancho
A6: Caja: interior (cavidad) | B6: 119.0 x 118.0 x 73.0 | C6: mm | D6: layout.py
A7: Caja: pared / fondo | B7: 4 / 4 | C7: mm | D7: params.py caja.pared, caja.fondo
A8: Nodo sobre el aro (de / a) | B8: -40 / 181 | C8: mm | D8: simple.py, nube de puntos del CAD
A9: Capsula: exterior | B9: 44.0 x 46.0 x 46.0 | C9: mm | D9: capsula.py cap_dims
A10: Capsula: angulo y acimut | B10: 30 grados, adentro | C10: - | D10: params.py capsula.angulo, capsula.acimut (equipo)
A11: Ventana: diametro x espesor | B11: 30 x 3 | C11: mm | D11: params.py ventana.*
A12: Gancho en C (fusionado al riel): C interior / pared / asiento | B12: 8.8 / 4 / 12 | C12: mm | D12: params.py aro.seccion, gancho.c
... A29: Camara en Ø500: lente a la red | B29: no corta la red | C29: mm | D29: simple.py camera_view (FOV y enfoque estimados)

Sheet INSTRUCCIONES
A1: LanternGuard | Hoja de medidas para el CAD
A3: Cómo llenarla (elige una):
A4: A) A mano: en la pestaña MEDIDAS llena solo las celdas amarillas (valor, origen, estado, quien, fecha). No cambies los nombres de la columna parametro: el script los lee tal cual.
A5: B) Con ChatGPT: sube este archivo a ChatGPT, pega el texto de abajo y luego dicta o escribe tus medidas (o sube fotos del calibrador). Te devuelve el mismo Excel lleno; descárgalo y mándaselo a Yoichi.
A7: TEXTO PARA PEGAR EN CHATGPT:
A8: Te subo el Excel "LanternGuard_MEDIDAS.xlsx". Tu trabajo es llenar la pestaña MEDIDAS con las medidas que te voy a dar, sin cambiar nada más. Reglas: 1. Solo escribe en las columnas valor, origen, estado, quien y fecha. No toques parametro, descripcion, como_medir ni unidad, y no agregues ni borres filas. 2. Lee descripcion y como_medir para saber a qué fila corresponde cada medida que te doy. Si no estás seguro, pregúntame antes de escribir. 3. Unidades: todo en mm salvo que la columna unidad diga otra cosa. Si te doy centímetros, conviértelos. Decimales con punto. 4. origen: "medido" si lo medí con calibrador o cinta; "fabricante" si lo saqué de la ficha técnica o la boleta; "estimado" si es a ojo. 5. estado: "confirmado" solo si origen es medido o fabricante. Si es estimado, "por_verificar". 6. quien: mi nombre. fecha: la de hoy, formato AAAA-MM-DD. 7. Si te doy un rango (ej. "entre 7.8 y 8.1"), pon el promedio y estado por_verificar. 8. Las filas que no te dé, déjalas vacías. Al final dime la lista de parámetros que quedaron sin llenar. 9. Devuélveme el mismo archivo Excel lleno, con el mismo nombre y las mismas pestañas. Mi nombre es: ___ Medidas:
A10: Columnas:
A11: parametro: nombre exacto que usa el script del CAD (no cambiar). descripcion: qué es. como_medir: cómo tomar la medida. unidad: mm o texto. valor: lo que mediste. origen: medido / fabricante / estimado. estado: confirmado / por_verificar. quien: quién midió. fecha: cuándo.
A13: Consejos:
A14: Mide 3 veces y anota el promedio. Para diámetros interiores usa las puntas de atrás del calibrador. Para el aro de la linterna mide en dos direcciones (puede estar ovalado); si difieren más de 5 mm anota el promedio con estado por_verificar. Una foto del calibrador mostrando la lectura vale más que la memoria.

Sheet MEDIDAS
A1: parametro | B1: descripcion | C1: como_medir | D1: unidad | E1: valor | F1: origen | G1: estado | H1: quien | I1: fecha | J1: nombre_en_params | K1: nota
A2: EJEMPLO (ignorar) | B2: Ejemplo de fila bien llenada | D2: mm | E2: 7.9 | F2: medido | G2: confirmado | H2: Gabi | I2: 2026-10-29
A3: ARO DE LA LINTERNA
A4: aro.diametro | B4: Diámetro del aro superior de la linterna, medido al centro del tubo | C4: Cinta métrica de borde a borde pasando por el centro, restar un espesor de tubo | D4: mm | E4: 200 | F4: equipo | G4: confirmado | H4: CAD | I4: 2026-10-29 | J4: simple.aro_D
A5: aro.seccion | B5: Espesor del tubo o alambre del aro | C5: Calibrador cerrado sobre el tubo, en 3 puntos distintos, anotar el promedio | D5: mm | E5: 8 | F5: estimado | G5: por_verificar | H5: CAD | I5: 2026-10-29 | J5: aro.seccion
A6: linterna.altura | B6: Altura total de la linterna de prueba (del aro superior a la base) | C6: Cinta métrica con la linterna colgada | D6: mm | E6: 200 | F6: estimado | G6: por_verificar | H6: CAD | I6: 2026-10-29 | J6: linterna.alto | K6: alto de la red de la linterna de referencia
A7: linterna.pisos | B7: Cantidad de pisos de la linterna de prueba | C7: Contar | D7: unidades | E7: 3 | F7: estimado | G7: por_verificar | H7: CAD | I7: 2026-10-29 | J7: linterna.pisos
A8: CÁMARA ARDUCAM MEGA 5MP
A9: camara.largo | B9: Largo de la placa de la cámara | C9: Calibrador, sin contar el conector | D9: mm | E9: 33 | F9: fabricante | G9: confirmado | H9: CAD | I9: 2026-10-29 | J9: camara.envolvente[0]
A10: camara.ancho | B10: Ancho de la placa de la cámara | C10: Calibrador | D10: mm | E10: 33 | F10: fabricante | G10: confirmado | H10: CAD | I10: 2026-10-29 | J10: camara.envolvente[1]
A11: camara.alto | B11: Alto total con el lente puesto | C11: Calibrador, desde la cara trasera de la placa hasta la punta del lente | D11: mm | E11: 17 | F11: fabricante | G11: confirmado | H11: CAD | I11: 2026-10-29 | J11: camara.envolvente[2]
A12: camara.cable_incluido | B12: Largo del cable plano que viene con la cámara | C12: Cinta métrica, cable estirado sin tensar, de conector a conector | D12: mm | E12: 300 | F12: fabricante | G12: por_verificar | H12: CAD | I12: 2026-10-29 | J12: camara.cable_incluido
A13: camara.agujero_diametro | B13: Diámetro de los agujeros de montaje de la placa | C13: Calibrador interior | D13: mm | K13: el CAD no usa los agujeros de la placa (la camara va calzada en la cavidad)
A14: camara.agujero_distancia | B14: Distancia entre centros de los agujeros de montaje | C14: Calibrador, centro a centro | D14: mm | K14: idem
A15: ARO LED
A16: aro_led.exterior | B16: Diámetro exterior del aro LED | C16: Calibrador | D16: mm | E16: 30 | F16: estimado | G16: por_verificar | H16: CAD | I16: 2026-10-29 | J16: aro_led.envolvente[0]
A17: aro_led.interior | B17: Diámetro interior del aro LED (el hueco) | C17: Calibrador interior | D17: mm | E17: 19 | F17: estimado | G17: por_verificar | H17: CAD | I17: 2026-10-29 | J17: aro_led.agujero
A18: aro_led.espesor | B18: Espesor del aro LED con sus componentes | C18: Calibrador, en la parte más gruesa | D18: mm | E18: 3 | F18: estimado | G18: por_verificar | H18: CAD | I18: 2026-10-29 | J18: aro_led.envolvente[1]
A19: ESP32-S3 (placa sola, sin KIT A)
A20: esp32.largo | B20: Largo de la placa | C20: Calibrador, incluyendo el conector USB si sobresale | D20: mm | E20: 69 | F20: estimado | G20: por_verificar | H20: CAD | I20: 2026-10-29 | J20: comp.esp32_devkitc1[0]
A21: esp32.ancho | B21: Ancho de la placa | C21: Calibrador | D21: mm | E21: 26 | F21: estimado | G21: por_verificar | H21: CAD | I21: 2026-10-29 | J21: comp.esp32_devkitc1[1]
A22: esp32.alto_con_headers | B22: Alto total con los pines (headers) puestos | C22: Calibrador, de la punta de los pines a lo más alto del otro lado | D22: mm | E22: 15 | F22: estimado | G22: por_verificar | H22: CAD | I22: 2026-10-29 | J22: comp.esp32_devkitc1[2]
A23: esp32.lado_usb | B23: En qué lado corto está el USB-C | C23: Texto: 'lado antena' o 'lado opuesto' | D23: texto | K23: el layout supone el USB en el lado corto u+ (layout.py), no es un parametro
A24: PCB DE LA BOYA (placa fabricada 70 x 73.5)
A25: pcb_boya.largo | B25: Largo real de la placa | C25: Calibrador | D25: mm | E25: 70 | F25: equipo | G25: por_verificar | H25: CAD | I25: 2026-10-29 | J25: boya.pcb[0]
A26: pcb_boya.ancho | B26: Ancho real de la placa | C26: Calibrador | D26: mm | E26: 73.5 | F26: equipo | G26: por_verificar | H26: CAD | I26: 2026-10-29 | J26: boya.pcb[1]
A27: pcb_boya.agujero_diametro | B27: Diámetro de los agujeros de montaje | C27: Calibrador interior | D27: mm | K27: la boya no fija la PCB por sus agujeros todavia
A28: pcb_boya.agujero_dist_esquina | B28: Distancia del centro del agujero a cada borde | C28: Calibrador, anotar las dos distancias (x e y) si son distintas | D28: mm | K28: idem
A29: pcb_boya.alto_componentes | B29: Alto máximo de lo que tiene encima (Heltec en headers + OLED) | C29: Calibrador, desde la cara inferior de la placa a lo más alto | D29: mm | E29: 25 | F29: estimado | G29: por_verificar | H29: CAD | I29: 2026-10-29 | J29: boya.alto_pcb_conectores
A30: ENERGÍA DE LA BOYA
A31: portabaterias.largo | B31: Largo del portabaterías 3 x 18650 | C31: Calibrador o regla | D31: mm | E31: 80 | F31: estimado | G31: por_verificar | H31: CAD | I31: 2026-10-29 | J31: boya.portabaterias[0]
A32: portabaterias.ancho | B32: Ancho del portabaterías | C32: Calibrador o regla | D32: mm | E32: 70 | F32: estimado | G32: por_verificar | H32: CAD | I32: 2026-10-29 | J32: boya.portabaterias[1]
A33: portabaterias.alto | B33: Alto del portabaterías con baterías puestas | C33: Calibrador | D33: mm | E33: 30 | F33: estimado | G33: por_verificar | H33: CAD | I33: 2026-10-29 | J33: boya.portabaterias[2]
A34: waveshare.largo | B34: Largo del Waveshare Solar Power Manager (D) | C34: Calibrador | D34: mm | E34: 45 | F34: fabricante | G34: confirmado | H34: CAD | I34: 2026-10-29 | J34: boya.waveshare_D[0]
A35: waveshare.ancho | B35: Ancho del Waveshare | C35: Calibrador | D35: mm | E35: 40 | F35: fabricante | G35: confirmado | H35: CAD | I35: 2026-10-29 | J35: boya.waveshare_D[1]
A36: waveshare.alto | B36: Alto del Waveshare con conectores | C36: Calibrador | D36: mm | E36: 10.1 | F36: fabricante | G36: confirmado | H36: CAD | I36: 2026-10-29 | J36: boya.waveshare_D[2]
A37: panel.largo | B37: Largo del panel solar | C37: Regla o cinta | D37: mm | E37: 170 | F37: estimado | G37: por_verificar | H37: CAD | I37: 2026-10-29 | J37: boya.panel[0]
A38: panel.ancho | B38: Ancho del panel solar | C38: Regla o cinta | D38: mm | E38: 170 | F38: estimado | G38: por_verificar | H38: CAD | I38: 2026-10-29 | J38: boya.panel[1]
A39: panel.espesor | B39: Espesor del panel solar | C39: Calibrador en el borde | D39: mm | E39: 3 | F39: estimado | G39: por_verificar | H39: CAD | I39: 2026-10-29 | J39: boya.panel[2]
A40: CABLES Y SELLADO
...
